<?xml version="1.0" encoding="utf-8"?>
<!-- This URDF was automatically created by SolidWorks to URDF Exporter! Originally created by Stephen Brawner (brawner@gmail.com) 
     Commit Version: 1.6.0-4-g7f85cfe  Build Version: 1.6.7995.38578
     For more information, please see http://wiki.ros.org/sw_urdf_exporter -->
<robot
  name="svan_urdf_package">
  <!-- <link name="world" />
  <joint name="world_joint" type="fixed">
      <origin xyz="0 0 0.5" />
      <parent link="world" />
      <child link="base_link" />
      <limit lower="0" upper="0" effort="1000" velocity="0" />
  </joint> -->
  <link
    name="base_link">
    <inertial>
      <origin
        xyz="-0.000736126189085237 -1.72251877519347E-05 9.8768329506848E-05"
        rpy="0 0 0" />
      <mass
        value="2.99710872609609" />
      <inertia
        ixx="0.00437980864562948"
        ixy="-3.84604566302649E-08"
        ixz="-6.89975946715173E-08"
        iyy="0.0107359870662536"
        iyz="4.61648347490341E-07"
        izz="0.0128759281709884" />
    </inertial>
    <visual>
      <origin
        xyz="0 0 0"
        rpy="0 0 0" />
      <geometry>
        <mesh
          filename="package://svan_urdf_package/meshes/torso_link.STL" />
      </geometry>
      <material
        name="">
        <color
          rgba="0.752941176470588 0.752941176470588 0.752941176470588 1" />
      </material>
    </visual>
    <collision>
      <origin
        xyz="0 0 0"
        rpy="0 0 0" />
      <geometry>
        <mesh
          filename="package://svan_urdf_package/meshes/torso_link.STL" />
      </geometry>
    </collision>
  </link>
  <link
    name="fr_abd_l">
    <inertial>
      <origin
        xyz="0.0431354666865266 -0.0619037967425595 -1.28783333823018E-05"
        rpy="0 0 0" />
      <mass
        value="0.547089526327116" />
      <inertia
        ixx="0.000195963974362415"
        ixy="6.55731584977151E-06"
        ixz="8.03607942102591E-10"
        iyy="0.000300416287485921"
        iyz="-1.87450618305707E-08"
        izz="0.000205685414875868" />
    </inertial>
    <visual>
      <origin
        xyz="0 0 0"
        rpy="0 0 0" />
      <geometry>
        <mesh
          filename="package://svan_urdf_package/meshes/fr_abd_l.STL" />
      </geometry>
      <material
        name="">
        <color
          rgba="0.752941176470588 0.752941176470588 0.752941176470588 1" />
      </material>
    </visual>
    <collision>
      <origin
        xyz="0 0 0"
        rpy="0 0 0" />
      <geometry>
        <mesh
          filename="package://svan_urdf_package/meshes/fr_abd_l.STL" />
      </geometry>
    </collision>
  </link>
  <joint
    name="fr_abd_j"
    type="revolute">
    <origin
      xyz="0.20368 -0.06 0"
      rpy="0 0 0" />
    <parent
      link="base_link" />
    <child
      link="fr_abd_l" />
    <axis
      xyz="-1 0 0" />
    <limit
      lower="-3"
      upper="3"
      effort="100"
      velocity="100" />
  </joint>
  <link
    name="fr_hip_l">
    <inertial>
      <origin
        xyz="0.00165916788705489 0.00999999412640479 -0.0713157899491978"
        rpy="0 0 0" />
      <mass
        value="0.147108571121328" />
      <inertia
        ixx="0.000309578662803665"
        ixy="3.78430545648715E-11"
        ixz="6.9914225906236E-06"
        iyy="0.000329310052837933"
        iyz="6.78580350895923E-11"
        izz="2.13859904286806E-05" />
    </inertial>
    <visual>
      <origin
        xyz="0 0 0"
        rpy="0 0 0" />
      <geometry>
        <mesh
          filename="package://svan_urdf_package/meshes/fr_hip_l.STL" />
      </geometry>
      <material
        name="">
        <color
          rgba="0.752941176470588 0.752941176470588 0.752941176470588 1" />
      </material>
    </visual>
    <collision>
      <origin
        xyz="0 0 0"
        rpy="0 0 0" />
      <geometry>
        <mesh
          filename="package://svan_urdf_package/meshes/fr_hip_l.STL" />
      </geometry>
    </collision>
  </link>
  <joint
    name="fr_hip_j"
    type="revolute">
    <origin
      xyz="0.043 -0.07525 0"
      rpy="0 0 0" />
    <parent
      link="fr_abd_l" />
    <child
      link="fr_hip_l" />
    <axis
      xyz="0 1 0" />
    <limit
      lower="-3"
      upper="3"
      effort="100"
      velocity="100" />
  </joint>
  <link
    name="fr_knee_l">
    <inertial>
      <origin
        xyz="0.00288556341815482 1.5445513158463E-06 -0.0756253134355262"
        rpy="0 0 0" />
      <mass
        value="0.122422228142348" />
      <inertia
        ixx="9.45801447821519E-05"
        ixy="-2.61144960906036E-09"
        ixz="6.78248943065743E-06"
        iyy="0.00011005271843826"
        iyz="-5.2727542858242E-09"
        izz="2.0670821626861E-05" />
    </inertial>
    <visual>
      <origin
        xyz="0 0 0"
        rpy="0 0 0" />
      <geometry>
        <mesh
          filename="package://svan_urdf_package/meshes/fr_knee_l.STL" />
      </geometry>
      <material
        name="">
        <color
          rgba="0.752941176470588 0.752941176470588 0.752941176470588 1" />
      </material>
    </visual>
    <collision>
      <origin
        xyz="0 0 0"
        rpy="0 0 0" />
      <geometry>
        <mesh
          filename="package://svan_urdf_package/meshes/fr_knee_l.STL" />
      </geometry>
    </collision>
  </link>
  <joint
    name="fr_knee_j"
    type="revolute">
    <origin
      xyz="0.0041389 0.01 -0.16494"
      rpy="0 0 0" />
    <parent
      link="fr_hip_l" />
    <child
      link="fr_knee_l" />
    <axis
      xyz="0 1 0" />
    <limit
      lower="-3"
      upper="3"
      effort="100"
      velocity="100" />
  </joint>
  <!-- <link
    name="fr_dummy_l">
    <inertial>
      <origin
        xyz="0.00149999142621271 3.05311331771918E-15 5.0716157441455E-06"
        rpy="0 0 0" />
      <mass
        value="9.42477796076937E-06" />
      <inertia
        ixx="4.71244285092067E-12"
        ixy="-3.43878520170761E-27"
        ixz="-1.59328596951608E-14"
        iyy="9.42477796076933E-12"
        iyz="-2.01948391735052E-28"
        izz="9.42472409023335E-12" />
    </inertial>
    <visual>
      <origin
        xyz="0 0 0"
        rpy="0 0 0" />
      <geometry>
        <mesh
          filename="package://svan_urdf_package/meshes/fr_dummy_l.STL" />
      </geometry>
      <material
        name="">
        <color
          rgba="0.792156862745098 0.819607843137255 0.933333333333333 1" />
      </material>
    </visual>
    <collision>
      <origin
        xyz="0 0 0"
        rpy="0 0 0" />
      <geometry>
        <mesh
          filename="package://svan_urdf_package/meshes/fr_dummy_l.STL" />
      </geometry>
    </collision>
  </link> -->
  <joint
    name="fr_dummy_j"
    type="fixed">
    <origin
      xyz="-0.026457 0 -0.16693"
      rpy="0 0 0" />
    <parent
      link="fr_knee_l" />
    <child
      link="foot_FR" />
    <!-- <limit lower="0" upper="0" effort="0" velocity="0" /> -->
    <axis
      xyz="0 0 0" />
  </joint>
  <link
    name="fl_abd_l">
    <inertial>
      <origin
        xyz="0.0431354666865253 0.0619037967425567 1.28783333771046E-05"
        rpy="0 0 0" />
      <mass
        value="0.547089526327068" />
      <inertia
        ixx="0.000195963974362192"
        ixy="-6.55731584978387E-06"
        ixz="-8.03607962880309E-10"
        iyy="0.000300416287485723"
        iyz="-1.87450617909673E-08"
        izz="0.000205685414875836" />
    </inertial>
    <visual>
      <origin
        xyz="0 0 0"
        rpy="0 0 0" />
      <geometry>
        <mesh
          filename="package://svan_urdf_package/meshes/fl_abd_l.STL" />
      </geometry>
      <material
        name="">
        <color
          rgba="0.752941176470588 0.752941176470588 0.752941176470588 1" />
      </material>
    </visual>
    <collision>
      <origin
        xyz="0 0 0"
        rpy="0 0 0" />
      <geometry>
        <mesh
          filename="package://svan_urdf_package/meshes/fl_abd_l.STL" />
      </geometry>
    </collision>
  </link>
  <joint
    name="fl_abd_j"
    type="revolute">
    <origin
      xyz="0.20368 0.06 0"
      rpy="0 0 0" />
    <parent
      link="base_link" />
    <child
      link="fl_abd_l" />
    <axis
      xyz="-1 0 0" />
    <limit
      lower="-3"
      upper="3"
      effort="100"
      velocity="100" />
  </joint>
  <link
    name="fl_hip_l">
    <inertial>
      <origin
        xyz="0.0016591678870552 -0.0100000058735955 -0.0713157899491955"
        rpy="0 0 0" />
      <mass
        value="0.147108571121327" />
      <inertia
        ixx="0.000309578662803818"
        ixy="3.78430545549379E-11"
        ixz="6.99142259045296E-06"
        iyy="0.000329310052838139"
        iyz="6.78580349989196E-11"
        izz="2.13859904287332E-05" />
    </inertial>
    <visual>
      <origin
        xyz="0 0 0"
        rpy="0 0 0" />
      <geometry>
        <mesh
          filename="package://svan_urdf_package/meshes/fl_hip_l.STL" />
      </geometry>
      <material
        name="">
        <color
          rgba="0.752941176470588 0.752941176470588 0.752941176470588 1" />
      </material>
    </visual>
    <collision>
      <origin
        xyz="0 0 0"
        rpy="0 0 0" />
      <geometry>
        <mesh
          filename="package://svan_urdf_package/meshes/fl_hip_l.STL" />
      </geometry>
    </collision>
  </link>
  <joint
    name="fl_hip_j"
    type="revolute">
    <origin
      xyz="0.043 0.07525 0"
      rpy="0 0 0" />
    <parent
      link="fl_abd_l" />
    <child
      link="fl_hip_l" />
    <axis
      xyz="0 1 0" />
    <limit
      lower="-3"
      upper="3"
      effort="100"
      velocity="100" />
  </joint>
  <link
    name="fl_knee_a">
    <inertial>
      <origin
        xyz="0.00288556341815421 1.54455131551323E-06 -0.0756253134355257"
        rpy="0 0 0" />
      <mass
        value="0.122422228142348" />
      <inertia
        ixx="9.45801447821233E-05"
        ixy="-2.61144960908792E-09"
        ixz="6.78248943063961E-06"
        iyy="0.000110052718438119"
        iyz="-5.27275428583716E-09"
        izz="2.0670821626749E-05" />
    </inertial>
    <visual>
      <origin
        xyz="0 0 0"
        rpy="0 0 0" />
      <geometry>
        <mesh
          filename="package://svan_urdf_package/meshes/fl_knee_a.STL" />
      </geometry>
      <material
        name="">
        <color
          rgba="0.752941176470588 0.752941176470588 0.752941176470588 1" />
      </material>
    </visual>
    <collision>
      <origin
        xyz="0 0 0"
        rpy="0 0 0" />
      <geometry>
        <mesh
          filename="package://svan_urdf_package/meshes/fl_knee_a.STL" />
      </geometry>
    </collision>
  </link>
  <joint
    name="fl_knee_j"
    type="revolute">
    <origin
      xyz="0.0041389 -0.01 -0.16494"
      rpy="0 0 0" />
    <parent
      link="fl_hip_l" />
    <child
      link="fl_knee_a" />
    <axis
      xyz="0 1 0" />
    <limit
      lower="-3"
      upper="3"
      effort="100"
      velocity="100" />
  </joint>
  <!-- <link
    name="fl_dummy_l">
    <inertial>
      <origin
        xyz="0.0014999914262166 2.55351295663786E-15 5.07161574681003E-06"
        rpy="0 0 0" />
      <mass
        value="9.42477796076937E-06" />
      <inertia
        ixx="4.71244285092067E-12"
        ixy="-1.7027390075873E-27"
        ixz="-1.59328596951634E-14"
        iyy="9.42477796076932E-12"
        iyz="-4.41762106934845E-29"
        izz="9.42472409023335E-12" />
    </inertial>
    <visual>
      <origin
        xyz="0 0 0"
        rpy="0 0 0" />
      <geometry>
        <mesh
          filename="package://svan_urdf_package/meshes/fl_dummy_l.STL" />
      </geometry>
      <material
        name="">
        <color
          rgba="0.792156862745098 0.819607843137255 0.933333333333333 1" />
      </material>
    </visual>
    <collision>
      <origin
        xyz="0 0 0"
        rpy="0 0 0" />
      <geometry>
        <mesh
          filename="package://svan_urdf_package/meshes/fl_dummy_l.STL" />
      </geometry>
    </collision>
  </link> -->
  <joint
    name="fl_dummy_j"
    type="fixed">
    <origin
      xyz="-0.026618 0 -0.16693"
      rpy="0 0 0" />
    <parent
      link="fl_knee_a" />
    <child
      link="foot_FL" />
    <axis
      xyz="0 0 0" />
    <!-- <limit lower="0" upper="0" effort="1000" velocity="0" /> -->
  </joint>
  <link
    name="rr_abd_l">
    <inertial>
      <origin
        xyz="-0.0408339071979818 -0.0619037967425603 0.000179250427446827"
        rpy="0 0 0" />
      <mass
        value="0.547089526327114" />
      <inertia
        ixx="0.000195963974362413"
        ixy="-6.63504112736179E-06"
        ixz="8.03607941529097E-10"
        iyy="0.000300416287485919"
        iyz="6.06375583261325E-10"
        izz="0.000205685414875867" />
    </inertial>
    <visual>
      <origin
        xyz="0 0 0"
        rpy="0 0 0" />
      <geometry>
        <mesh
          filename="package://svan_urdf_package/meshes/rr_abd_l.STL" />
      </geometry>
      <material
        name="">
        <color
          rgba="0.752941176470588 0.752941176470588 0.752941176470588 1" />
      </material>
    </visual>
    <collision>
      <origin
        xyz="0 0 0"
        rpy="0 0 0" />
      <geometry>
        <mesh
          filename="package://svan_urdf_package/meshes/rr_abd_l.STL" />
      </geometry>
    </collision>
  </link>
  <joint
    name="rr_abd_j"
    type="revolute">
    <origin
      xyz="-0.20482 -0.06 0"
      rpy="0 0 0" />
    <parent
      link="base_link" />
    <child
      link="rr_abd_l" />
    <axis
      xyz="1 0 0" />
    <limit
      lower="-3"
      upper="3"
      effort="100"
      velocity="100" />
  </joint>
  <link
    name="rr_hip_l">
    <inertial>
      <origin
        xyz="-0.00165916788705478 0.0100000058735978 -0.0713157899491982"
        rpy="0 0 0" />
      <mass
        value="0.147108571121328" />
      <inertia
        ixx="0.000309578662803667"
        ixy="3.78430547339955E-11"
        ixz="-6.99142259061868E-06"
        iyy="0.000329310052837923"
        iyz="-6.78580243498918E-11"
        izz="2.1385990428668E-05" />
    </inertial>
    <visual>
      <origin
        xyz="0 0 0"
        rpy="0 0 0" />
      <geometry>
        <mesh
          filename="package://svan_urdf_package/meshes/rr_hip_l.STL" />
      </geometry>
      <material
        name="">
        <color
          rgba="0.752941176470588 0.752941176470588 0.752941176470588 1" />
      </material>
    </visual>
    <collision>
      <origin
        xyz="0 0 0"
        rpy="0 0 0" />
      <geometry>
        <mesh
          filename="package://svan_urdf_package/meshes/rr_hip_l.STL" />
      </geometry>
    </collision>
  </link>
  <joint
    name="rr_hip_j"
    type="revolute">
    <origin
      xyz="-0.043 -0.07525 0"
      rpy="0 0 0" />
    <parent
      link="rr_abd_l" />
    <child
      link="rr_hip_l" />
    <axis
      xyz="0 -1 0" />
    <limit
      lower="-3"
      upper="3"
      effort="100"
      velocity="100" />
  </joint>
  <link
    name="rr_knee_l">
    <inertial>
      <origin
        xyz="0.00654595759568111 1.5446183047052E-06 -0.0753966327483542"
        rpy="0 0 0" />
      <mass
        value="0.122422246876929" />
      <inertia
        ixx="9.37491120274394E-05"
        ixy="-2.35343019264926E-09"
        ixz="1.03265117822068E-05"
        iyy="0.000110051537971271"
        iyz="-5.39219781160484E-09"
        izz="2.15006699644239E-05" />
    </inertial>
    <visual>
      <origin
        xyz="0 0 0"
        rpy="0 0 0" />
      <geometry>
        <mesh
          filename="package://svan_urdf_package/meshes/rr_knee_l.STL" />
      </geometry>
      <material
        name="">
        <color
          rgba="0.752941176470588 0.752941176470588 0.752941176470588 1" />
      </material>
    </visual>
    <collision>
      <origin
        xyz="0 0 0"
        rpy="0 0 0" />
      <geometry>
        <mesh
          filename="package://svan_urdf_package/meshes/rr_knee_l.STL" />
      </geometry>
    </collision>
  </link>
  <joint
    name="rr_knee_j"
    type="revolute">
    <origin
      xyz="-0.0038618 0.01 -0.16493"
      rpy="0 0 0" />
    <parent
      link="rr_hip_l" />
    <child
      link="rr_knee_l" />
    <axis
      xyz="0 1 0" />
    <limit
      lower="-3"
      upper="3"
      effort="100"
      velocity="100" />
  </joint>
  <!-- <link
    name="rr_dummy_l">
    <inertial>
      <origin
        xyz="0.00149798440726828 3.10862446895044E-15 7.7734905568394E-05"
        rpy="0 0 0" />
      <mass
        value="9.42477796076944E-06" />
      <inertia
        ixx="4.72504481421764E-12"
        ixy="-1.40725882958467E-27"
        ixz="-2.43883254369301E-13"
        iyy="9.42477796076952E-12"
        iyz="-7.74661408927972E-29"
        izz="9.41212212693661E-12" />
    </inertial>
    <visual>
      <origin
        xyz="0 0 0"
        rpy="0 0 0" />
      <geometry>
        <mesh
          filename="package://svan_urdf_package/meshes/rr_dummy_l.STL" />
      </geometry>
      <material
        name="">
        <color
          rgba="0.792156862745098 0.819607843137255 0.933333333333333 1" />
      </material>
    </visual>
    <collision>
      <origin
        xyz="0 0 0"
        rpy="0 0 0" />
      <geometry>
        <mesh
          filename="package://svan_urdf_package/meshes/rr_dummy_l.STL" />
      </geometry>
    </collision>
  </link> -->
  <joint
    name="rr_dummy_j"
    type="fixed">
    <origin
      xyz="-0.018339 0 -0.16802"
      rpy="0 0 0" />
    <parent
      link="rr_knee_l" />
    <child
      link="foot_RR" />
    <!-- <limit lower="0" upper="0" effort="1000" velocity="0" /> -->
    <axis
      xyz="0 0 0" />
  </joint>
  <link
    name="rl_abd_l">
    <inertial>
      <origin
        xyz="-0.0408339071979842 0.0619037967425569 -0.000179250427450348"
        rpy="0 0 0" />
      <mass
        value="0.547089526327067" />
      <inertia
        ixx="0.000195963974362192"
        ixy="6.6350411273486E-06"
        ixz="-8.03607962384451E-10"
        iyy="0.000300416287485722"
        iyz="6.06375623877521E-10"
        izz="0.000205685414875835" />
    </inertial>
    <visual>
      <origin
        xyz="0 0 0"
        rpy="0 0 0" />
      <geometry>
        <mesh
          filename="package://svan_urdf_package/meshes/rl_abd_l.STL" />
      </geometry>
      <material
        name="">
        <color
          rgba="0.752941176470588 0.752941176470588 0.752941176470588 1" />
      </material>
    </visual>
    <collision>
      <origin
        xyz="0 0 0"
        rpy="0 0 0" />
      <geometry>
        <mesh
          filename="package://svan_urdf_package/meshes/rl_abd_l.STL" />
      </geometry>
    </collision>
  </link>
  <joint
    name="rl_abd_j"
    type="revolute">
    <origin
      xyz="-0.20482 0.06 0"
      rpy="0 0 0" />
    <parent
      link="base_link" />
    <child
      link="rl_abd_l" />
    <axis
      xyz="1 0 0" />
    <limit
      lower="-3"
      upper="3"
      effort="100"
      velocity="100" />
  </joint>
  <link
    name="rl_hip_l">
    <inertial>
      <origin
        xyz="-0.00179950691259256 -0.0100000058735954 -0.0713123896470731"
        rpy="0 0 0" />
      <mass
        value="0.147108560926126" />
      <inertia
        ixx="0.000309580559412878"
        ixy="4.14968005699223E-11"
        ixz="-6.9946474189349E-06"
        iyy="0.00032931216560272"
        iyz="6.56222779612308E-11"
        izz="2.13861970709628E-05" />
    </inertial>
    <visual>
      <origin
        xyz="0 0 0"
        rpy="0 0 0" />
      <geometry>
        <mesh
          filename="package://svan_urdf_package/meshes/rl_hip_l.STL" />
      </geometry>
      <material
        name="">
        <color
          rgba="0.752941176470588 0.752941176470588 0.752941176470588 1" />
      </material>
    </visual>
    <collision>
      <origin
        xyz="0 0 0"
        rpy="0 0 0" />
      <geometry>
        <mesh
          filename="package://svan_urdf_package/meshes/rl_hip_l.STL" />
      </geometry>
    </collision>
  </link>
  <joint
    name="rl_hip_j"
    type="revolute">
    <origin
      xyz="-0.043 0.07525 0"
      rpy="0 0 0" />
    <parent
      link="rl_abd_l" />
    <child
      link="rl_hip_l" />
    <axis
      xyz="0 1 0" />
    <limit
      lower="-3"
      upper="3"
      effort="100"
      velocity="100" />
  </joint>
  <link
    name="rl_knee_l">
    <inertial>
      <origin
        xyz="0.00654594639576345 1.54461741741496E-06 -0.0753966803284335"
        rpy="0 0 0" />
      <mass
        value="0.122422317176859" />
      <inertia
        ixx="9.3749108734946E-05"
        ixy="-2.3534371458569E-09"
        ixz="1.03265058974487E-05"
        iyy="0.000110051571045759"
        iyz="-5.39219909611954E-09"
        izz="2.15007107251529E-05" />
    </inertial>
    <visual>
      <origin
        xyz="0 0 0"
        rpy="0 0 0" />
      <geometry>
        <mesh
          filename="package://svan_urdf_package/meshes/rl_knee_l.STL" />
      </geometry>
      <material
        name="">
        <color
          rgba="0.752941176470588 0.752941176470588 0.752941176470588 1" />
      </material>
    </visual>
    <collision>
      <origin
        xyz="0 0 0"
        rpy="0 0 0" />
      <geometry>
        <mesh
          filename="package://svan_urdf_package/meshes/rl_knee_l.STL" />
      </geometry>
    </collision>
  </link>
  <joint
    name="rl_knee_j"
    type="revolute">
    <origin
      xyz="-0.0038618 -0.01 -0.16493"
      rpy="0 0 0" />
    <parent
      link="rl_hip_l" />
    <child
      link="rl_knee_l" />
    <axis
      xyz="0 1 0" />
    <limit
      lower="-3"
      upper="3"
      effort="100"
      velocity="100" />
  </joint>
  <!-- <link
    name="rl_dummy_l">
    <inertial>
      <origin
        xyz="0.0014979844072685 1.99840144432528E-15 7.77349055681165E-05"
        rpy="0 0 0" />
      <mass
        value="9.42477796076945E-06" />
      <inertia
        ixx="4.72504481421764E-12"
        ixy="-2.75052131823419E-27"
        ixz="-2.43883254369304E-13"
        iyy="9.42477796076952E-12"
        iyz="2.68212707776922E-29"
        izz="9.41212212693661E-12" />
    </inertial>
    <visual>
      <origin
        xyz="0 0 0"
        rpy="0 0 0" />
      <geometry>
        <mesh
          filename="package://svan_urdf_package/meshes/rl_dummy_l.STL" />
      </geometry>
      <material
        name="">
        <color
          rgba="0.792156862745098 0.819607843137255 0.933333333333333 1" />
      </material>
    </visual>
    <collision>
      <origin
        xyz="0 0 0"
        rpy="0 0 0" />
      <geometry>
        <mesh
          filename="package://svan_urdf_package/meshes/rl_dummy_l.STL" />
      </geometry>
    </collision>
  </link> -->
  <link name="foot_FR">
    <inertial>
        <origin xyz="0.0014979844072685 1.99840144432528E-15 7.77349055681165E-05"
        rpy="0 0 0" /> 
        <mass value="0.025" />
        <inertia ixx="2e-6" ixy="0" ixz="0" iyy="2e-6" iyz="0" izz="2e-6" />
      </inertial>
      <visual>
        <origin xyz="0 0 0" rpy="0 0 0" />
        <geometry>
          <sphere radius="0.01" />
        </geometry>
      </visual>
      <collision>
        <origin xyz="0 0 0" rpy="0 0 0" />
        <geometry>
          <sphere radius="0.01" />
        </geometry>
      </collision>
  </link>
  <link name="foot_FL">
    <inertial>
        <origin xyz="0.0014979844072685 1.99840144432528E-15 7.77349055681165E-05"
        rpy="0 0 0" /> 
        <mass value="0.025" />
        <inertia ixx="2e-6" ixy="0" ixz="0" iyy="2e-6" iyz="0" izz="2e-6" />
      </inertial>
      <visual>
        <origin xyz="0 0 0" rpy="0 0 0" />
        <geometry>
          <sphere radius="0.01" />
        </geometry>
      </visual>
      <collision>
        <origin xyz="0 0 0" rpy="0 0 0" />
        <geometry>
          <sphere radius="0.01" />
        </geometry>
      </collision>
  </link>
  <link name="foot_RL">
    <inertial>
        <origin xyz="0.0014979844072685 1.99840144432528E-15 7.77349055681165E-05"
        rpy="0 0 0" /> 
        <mass value="0.025" />
        <inertia ixx="2e-6" ixy="0" ixz="0" iyy="2e-6" iyz="0" izz="2e-6" />
      </inertial>
      <visual>
        <origin xyz="0 0 0" rpy="0 0 0" />
        <geometry>
          <sphere radius="0.01" />
        </geometry>
      </visual>
      <collision>
        <origin xyz="0 0 0" rpy="0 0 0" />
        <geometry>
          <sphere radius="0.01" />
        </geometry>
      </collision>
  </link>
  <link name="foot_RR">
    <inertial>
        <origin xyz="0.0014979844072685 1.99840144432528E-15 7.77349055681165E-05"
        rpy="0 0 0" /> 
        <mass value="0.025" />
        <inertia ixx="2e-6" ixy="0" ixz="0" iyy="2e-6" iyz="0" izz="2e-6" />
      </inertial>
      <visual>
        <origin xyz="0 0 0" rpy="0 0 0" />
        <geometry>
          <sphere radius="0.01" />
        </geometry>
      </visual>
      <collision>
        <origin xyz="0 0 0" rpy="0 0 0" />
        <geometry>
          <sphere radius="0.01" />
        </geometry>
      </collision>
  </link>
  <joint
    name="rl_dummy_j"
    type="fixed">
    <origin
      xyz="-0.0185 0 -0.16802"
      rpy="0 0 0" />
    <parent
      link="rl_knee_l" />
    <child
      link="foot_RL" />
    <axis
      xyz="0 0 0" />
    <!-- <limit lower="0" upper="0" effort="1000" velocity="0" /> -->
  </joint>
</robot>