<?xml version="1.0" encoding="utf-8"?>
<!-- This URDF was automatically created by SolidWorks to URDF Exporter! Originally created by Stephen Brawner (brawner@gmail.com) 
     Commit Version: 1.6.0-4-g7f85cfe  Build Version: 1.6.7995.38578
     For more information, please see http://wiki.ros.org/sw_urdf_exporter -->
<robot
  name="svan_urdf_package">
  <link name="base">
    <visual>
      <origin rpy="0 0 0" xyz="0 0 0"/>
      <geometry>
        <box size="0.001 0.001 0.001"/>
      </geometry>
    </visual>
  </link> 
  <joint name="floating_base" type="fixed">
    <origin rpy="0 0 0" xyz="0 0 0"/>
    <parent link="base"/>
    <child link="trunk"/>
  </joint>

  <link name="trunk">
    <inertial>
      <origin
        xyz="-0.000736126189085237 -1.72251877519347E-05 9.8768329506848E-05"
        rpy="0 0 0" />
      <mass
        value="2.99710872609609" />
      <inertia
        ixx="0.00437980864562948"
        ixy="-3.84604566302649E-08"
        ixz="-6.89975946715173E-08"
        iyy="0.0107359870662536"
        iyz="4.61648347490341E-07"
        izz="0.0128759281709884" />
    </inertial>
    <visual>
      <origin
        xyz="0 0 0"
        rpy="0 0 0" />
      <geometry>
        <mesh
          filename="../meshes/torso_link.STL" />
      </geometry>
      <material
        name="">
        <color
          rgba="0.752941176470588 0.752941176470588 0.752941176470588 1" />
      </material>
    </visual>
    <collision>
      <origin rpy="0 0 0" xyz="0 0 0"/>
      <geometry>
        <box size="0.267 0.194 0.114"/>
      </geometry>
    </collision>
  </link>
  <link name="FR_hip">
    <inertial>
      <origin
        xyz="0.0431354666865266 -0.0619037967425595 -1.28783333823018E-05"
        rpy="0 0 0" />
      <mass
        value="0.547089526327116" />
      <inertia
        ixx="0.000195963974362415"
        ixy="6.55731584977151E-06"
        ixz="8.03607942102591E-10"
        iyy="0.000300416287485921"
        iyz="-1.87450618305707E-08"
        izz="0.000205685414875868" />
    </inertial>
    <visual>
      <origin
        xyz="0 0 0"
        rpy="0 0 0" />
      <geometry>
        <mesh
          filename="../meshes/fr_abd_l.STL" />
      </geometry>
      <material
        name="">
        <color
          rgba="0.752941176470588 0.752941176470588 0.752941176470588 1" />
      </material>
    </visual>
    <!-- <collision>
      <origin
        xyz="0 0 0"
        rpy="0 0 0" />
      <geometry>
        <mesh
          filename="../meshes/fr_abd_l.STL" />
      </geometry>
    </collision> -->
  </link>
  <joint name="FR_hip_joint" type="revolute">
    <origin
      xyz="0.20368 -0.06 0"
      rpy="0 0 0" />
    <parent
      link="trunk" />
    <child
      link="FR_hip" />
    <axis
      xyz="1 0 0" />
    <dynamics damping="0" friction="0"/>
    <limit
      lower="-0.8"
      upper="0.8"
      effort="20"
      velocity="52.4" />
  </joint>
  <link name="FR_thigh">
    <inertial>
      <origin
        xyz="0.00165916788705489 0.00999999412640479 -0.0713157899491978"
        rpy="0 0 0" />
      <mass
        value="0.147108571121328" />
      <inertia
        ixx="0.000309578662803665"
        ixy="3.78430545648715E-11"
        ixz="6.9914225906236E-06"
        iyy="0.000329310052837933"
        iyz="6.78580350895923E-11"
        izz="2.13859904286806E-05" />
    </inertial>
    <visual>
      <origin
        xyz="0 0 0"
        rpy="0 0 0" />
      <geometry>
        <mesh
          filename="../meshes/fr_hip_l.STL" />
      </geometry>
      <material
        name="">
        <color
          rgba="0.752941176470588 0.752941176470588 0.752941176470588 1" />
      </material>
    </visual>
    <collision>
      <origin
        xyz="0 0 0"
        rpy="0 0 0" />
      <geometry>
        <box size="0.2 0.0245 0.034"/>
      </geometry>
    </collision>
  </link>
  <joint name="FR_thigh_joint" type="revolute">
    <origin
      xyz="0.043 -0.07525 0"
      rpy="0 0 0" />
    <parent
      link="FR_hip" />
    <child
      link="FR_thigh" />
    <axis
      xyz="0 1 0" />
    <dynamics friction="0" damping="0"/>
    <limit effort="55" lower="-1.0471975512" upper="4.18879020479" velocity="28.6"/>
  </joint>
  <link name="FR_calf">
    <inertial>
      <origin
        xyz="0.00288556341815482 1.5445513158463E-06 -0.0756253134355262"
        rpy="0 0 0" />
      <mass
        value="0.122422228142348" />
      <inertia
        ixx="9.45801447821519E-05"
        ixy="-2.61144960906036E-09"
        ixz="6.78248943065743E-06"
        iyy="0.00011005271843826"
        iyz="-5.2727542858242E-09"
        izz="2.0670821626861E-05" />
    </inertial>
    <visual>
      <origin
        xyz="0 0 0"
        rpy="0 0 0" />
      <geometry>
        <mesh
          filename="../meshes/fr_knee_l.STL" />
      </geometry>
      <material
        name="">
        <color
          rgba="0.752941176470588 0.752941176470588 0.752941176470588 1" />
      </material>
    </visual>
    <collision>
      <origin
        xyz="0 0 0"
        rpy="0 0 0" />
      <geometry>
        <box size="0.2 0.016 0.016"/>
      </geometry>
    </collision>
  </link>
  <joint name="FR_calf_joint" type="revolute">
    <origin
      xyz="0.0041389 0.01 -0.16494"
      rpy="0 0 0" />
    <parent
      link="FR_thigh" />
    <child
      link="FR_calf" />
    <axis
      xyz="0 1 0" />
    <dynamics damping="0" friction="0"/>
    <limit effort="55" lower="-2.69653369433" upper="-0.916297857297" velocity="28.6"/>
  </joint>
  <joint name="FR_foot_fixed" type="fixed" dont_collapse="true">
    <origin
      xyz="-0.026457 0 -0.16693"
      rpy="0 0 0" />
    <parent
      link="FR_calf" />
    <child
      link="FR_foot" />
  </joint>
  <link name="FL_hip">
    <inertial>
      <origin
        xyz="0.0431354666865253 0.0619037967425567 1.28783333771046E-05"
        rpy="0 0 0" />
      <mass
        value="0.547089526327068" />
      <inertia
        ixx="0.000195963974362192"
        ixy="-6.55731584978387E-06"
        ixz="-8.03607962880309E-10"
        iyy="0.000300416287485723"
        iyz="-1.87450617909673E-08"
        izz="0.000205685414875836" />
    </inertial>
    <visual>
      <origin
        xyz="0 0 0"
        rpy="0 0 0" />
      <geometry>
        <mesh
          filename="../meshes/fl_abd_l.STL" />
      </geometry>
      <material
        name="">
        <color
          rgba="0.752941176470588 0.752941176470588 0.752941176470588 1" />
      </material>
    </visual>
    <!-- <collision>
      <origin
        xyz="0 0 0"
        rpy="0 0 0" />
      <geometry>
        <mesh
          filename="../meshes/fl_abd_l.STL" />
      </geometry>
    </collision> -->
  </link>
  <joint name="FL_hip_joint" type="revolute">
    <origin
      xyz="0.20368 0.06 0"
      rpy="0 0 0" />
    <parent
      link="trunk" />
    <child
      link="FL_hip" />
    <axis
      xyz="1 0 0" />
    <dynamics damping="0" friction="0"/>
    <limit effort="20" lower="-0.802851455917" upper="0.802851455917" velocity="52.4"/>
    </joint>
  <link name="FL_thigh">
    <inertial>
      <origin
        xyz="0.0016591678870552 -0.0100000058735955 -0.0713157899491955"
        rpy="0 0 0" />
      <mass
        value="0.147108571121327" />
      <inertia
        ixx="0.000309578662803818"
        ixy="3.78430545549379E-11"
        ixz="6.99142259045296E-06"
        iyy="0.000329310052838139"
        iyz="6.78580349989196E-11"
        izz="2.13859904287332E-05" />
    </inertial>
    <visual>
      <origin
        xyz="0 0 0"
        rpy="0 0 0" />
      <geometry>
        <mesh
          filename="../meshes/fl_hip_l.STL" />
      </geometry>
      <material
        name="">
        <color
          rgba="0.752941176470588 0.752941176470588 0.752941176470588 1" />
      </material>
    </visual>
    <collision>
      <origin
        xyz="0 0 0"
        rpy="0 0 0" />
      <geometry>
        <box size="0.2 0.0245 0.034"/>
      </geometry>
    </collision>
  </link>
  <joint name="FL_thigh_joint" type="revolute">
    <origin
      xyz="0.043 0.07525 0"
      rpy="0 0 0" />
    <parent
      link="FL_hip" />
    <child
      link="FL_thigh" />
    <axis
      xyz="0 1 0" />
    <dynamics damping="0" friction="0"/>
    <limit effort="55" lower="-1.0471975512" upper="4.18879020479" velocity="28.6"/>
  </joint>
  <link name="FL_calf">
    <inertial>
      <origin
        xyz="0.00288556341815421 1.54455131551323E-06 -0.0756253134355257"
        rpy="0 0 0" />
      <mass
        value="0.122422228142348" />
      <inertia
        ixx="9.45801447821233E-05"
        ixy="-2.61144960908792E-09"
        ixz="6.78248943063961E-06"
        iyy="0.000110052718438119"
        iyz="-5.27275428583716E-09"
        izz="2.0670821626749E-05" />
    </inertial>
    <visual>
      <origin
        xyz="0 0 0"
        rpy="0 0 0" />
      <geometry>
        <mesh
          filename="../meshes/fl_knee_a.STL" />
      </geometry>
      <material
        name="">
        <color
          rgba="0.752941176470588 0.752941176470588 0.752941176470588 1" />
      </material>
    </visual>
    <collision>
      <origin
        xyz="0 0 0"
        rpy="0 0 0" />
      <geometry>
        <box size="0.2 0.016 0.016"/>
      </geometry>
    </collision>
  </link>
  <joint name="FL_calf_joint" type="revolute">
    <origin
      xyz="0.0041389 -0.01 -0.16494"
      rpy="0 0 0" />
    <parent
      link="FL_thigh" />
    <child
      link="FL_calf" />
    <axis
      xyz="0 1 0" />
    <dynamics damping="0" friction="0"/>
    <limit effort="55" lower="-2.69653369433" upper="-0.916297857297" velocity="28.6"/>
  </joint>
  <joint name="FL_foot_fixed" type="fixed" dont_collapse="true">
    <origin
      xyz="-0.026618 0 -0.16693"
      rpy="0 0 0" />
    <parent
      link="FL_calf" />
    <child
      link="FL_foot" />
  </joint>
  <link name="RR_hip">
    <inertial>
      <origin
        xyz="-0.0408339071979818 -0.0619037967425603 0.000179250427446827"
        rpy="0 0 0" />
      <mass
        value="0.547089526327114" />
      <inertia
        ixx="0.000195963974362413"
        ixy="-6.63504112736179E-06"
        ixz="8.03607941529097E-10"
        iyy="0.000300416287485919"
        iyz="6.06375583261325E-10"
        izz="0.000205685414875867" />
    </inertial>
    <visual>
      <origin
        xyz="0 0 0"
        rpy="0 0 0" />
      <geometry>
        <mesh
          filename="../meshes/rr_abd_l.STL" />
      </geometry>
      <material
        name="">
        <color
          rgba="0.752941176470588 0.752941176470588 0.752941176470588 1" />
      </material>
    </visual>
    <!-- <collision>
      <origin
        xyz="0 0 0"
        rpy="0 0 0" />
      <geometry>
        <mesh
          filename="../meshes/rr_abd_l.STL" />
      </geometry>
    </collision> -->
  </link>
  <joint name="RR_hip_joint" type="revolute">
    <origin
      xyz="-0.20482 -0.06 0"
      rpy="0 0 0" />
    <parent
      link="trunk" />
    <child
      link="RR_hip" />
    <axis
      xyz="1 0 0" />
    <dynamics damping="0" friction="0"/>
    <limit effort="20" lower="-0.802851455917" upper="0.802851455917" velocity="52.4"/>
  </joint>
  <link name="RR_thigh">
    <inertial>
      <origin
        xyz="-0.00165916788705478 0.0100000058735978 -0.0713157899491982"
        rpy="0 0 0" />
      <mass
        value="0.147108571121328" />
      <inertia
        ixx="0.000309578662803667"
        ixy="3.78430547339955E-11"
        ixz="-6.99142259061868E-06"
        iyy="0.000329310052837923"
        iyz="-6.78580243498918E-11"
        izz="2.1385990428668E-05" />
    </inertial>
    <visual>
      <origin
        xyz="0 0 0"
        rpy="0 0 0" />
      <geometry>
        <mesh
          filename="../meshes/rr_hip_l.STL" />
      </geometry>
      <material
        name="">
        <color
          rgba="0.752941176470588 0.752941176470588 0.752941176470588 1" />
      </material>
    </visual>
    <collision>
      <origin
        xyz="0 0 0"
        rpy="0 0 0" />
      <geometry>
        <box size="0.2 0.0245 0.034"/>
      </geometry>
    </collision>
  </link>
  <joint name="RR_thigh_joint" type="revolute">
    <origin
      xyz="-0.043 -0.07525 0"
      rpy="0 0 0" />
    <parent
      link="RR_hip" />
    <child
      link="RR_thigh" />
    <axis
      xyz="0 1 0" />
    <dynamics damping="0" friction="0"/>
    <limit effort="55" lower="-1.0471975512" upper="4.18879020479" velocity="28.6"/>
  </joint>
  <link name="RR_calf">
    <inertial>
      <origin
        xyz="0.00654595759568111 1.5446183047052E-06 -0.0753966327483542"
        rpy="0 0 0" />
      <mass
        value="0.122422246876929" />
      <inertia
        ixx="9.37491120274394E-05"
        ixy="-2.35343019264926E-09"
        ixz="1.03265117822068E-05"
        iyy="0.000110051537971271"
        iyz="-5.39219781160484E-09"
        izz="2.15006699644239E-05" />
    </inertial>
    <visual>
      <origin
        xyz="0 0 0"
        rpy="0 0 0" />
      <geometry>
        <mesh
          filename="../meshes/rr_knee_l.STL" />
      </geometry>
      <material
        name="">
        <color
          rgba="0.752941176470588 0.752941176470588 0.752941176470588 1" />
      </material>
    </visual>
    <collision>
      <origin
        xyz="0 0 0"
        rpy="0 0 0" />
      <geometry>
        <box size="0.2 0.016 0.016"/>
      </geometry>
    </collision>
  </link>
  <joint name="RR_calf_joint" type="revolute">
    <origin
      xyz="-0.0038618 0.01 -0.16493"
      rpy="0 0 0" />
    <parent
      link="RR_thigh" />
    <child
      link="RR_calf" />
    <axis
      xyz="0 1 0" />
    <dynamics damping="0" friction="0"/>
    <limit effort="55" lower="-2.69653369433" upper="-0.916297857297" velocity="28.6"/>
  </joint>
  <!-- <link
    name="rr_dummy_l">
    <inertial>
      <origin
        xyz="0.00149798440726828 3.10862446895044E-15 7.7734905568394E-05"
        rpy="0 0 0" />
      <mass
        value="9.42477796076944E-06" />
      <inertia
        ixx="4.72504481421764E-12"
        ixy="-1.40725882958467E-27"
        ixz="-2.43883254369301E-13"
        iyy="9.42477796076952E-12"
        iyz="-7.74661408927972E-29"
        izz="9.41212212693661E-12" />
    </inertial>
    <visual>
      <origin
        xyz="0 0 0"
        rpy="0 0 0" />
      <geometry>
        <mesh
          filename="../meshes/rr_dummy_l.STL" />
      </geometry>
      <material
        name="">
        <color
          rgba="0.792156862745098 0.819607843137255 0.933333333333333 1" />
      </material>
    </visual>
    <collision>
      <origin
        xyz="0 0 0"
        rpy="0 0 0" />
      <geometry>
        <mesh
          filename="../meshes/rr_dummy_l.STL" />
      </geometry>
    </collision>
  </link> -->
  <joint name="RR_foot_fixed" type="fixed" dont_collapse="true">
    <origin
      xyz="-0.018339 0 -0.16802"
      rpy="0 0 0" />
    <parent
      link="RR_calf" />
    <child
      link="RR_foot" />
  </joint>
  <link name="RL_hip">
    <inertial>
      <origin
        xyz="-0.0408339071979842 0.0619037967425569 -0.000179250427450348"
        rpy="0 0 0" />
      <mass
        value="0.547089526327067" />
      <inertia
        ixx="0.000195963974362192"
        ixy="6.6350411273486E-06"
        ixz="-8.03607962384451E-10"
        iyy="0.000300416287485722"
        iyz="6.06375623877521E-10"
        izz="0.000205685414875835" />
    </inertial>
    <visual>
      <origin
        xyz="0 0 0"
        rpy="0 0 0" />
      <geometry>
        <mesh
          filename="../meshes/rl_abd_l.STL" />
      </geometry>
      <material
        name="">
        <color
          rgba="0.752941176470588 0.752941176470588 0.752941176470588 1" />
      </material>
    </visual>
    <!-- <collision>
      <origin
        xyz="0 0 0"
        rpy="0 0 0" />
      <geometry>
        <mesh
          filename="../meshes/rl_abd_l.STL" />
      </geometry>
    </collision> -->
  </link>
  <joint name="RL_hip_joint" type="revolute">
    <origin
      xyz="-0.20482 0.06 0"
      rpy="0 0 0" />
    <parent
      link="trunk" />
    <child
      link="RL_hip" />
    <axis
      xyz="1 0 0" />
    <dynamics damping="0" friction="0"/>
    <limit effort="20" lower="-0.802851455917" upper="0.802851455917" velocity="52.4"/>
  </joint>
  <link name="RL_thigh">
    <inertial>
      <origin
        xyz="-0.00179950691259256 -0.0100000058735954 -0.0713123896470731"
        rpy="0 0 0" />
      <mass
        value="0.147108560926126" />
      <inertia
        ixx="0.000309580559412878"
        ixy="4.14968005699223E-11"
        ixz="-6.9946474189349E-06"
        iyy="0.00032931216560272"
        iyz="6.56222779612308E-11"
        izz="2.13861970709628E-05" />
    </inertial>
    <visual>
      <origin
        xyz="0 0 0"
        rpy="0 0 0" />
      <geometry>
        <mesh
          filename="../meshes/rl_hip_l.STL" />
      </geometry>
      <material
        name="">
        <color
          rgba="0.752941176470588 0.752941176470588 0.752941176470588 1" />
      </material>
    </visual>
    <collision>
      <origin
        xyz="0 0 0"
        rpy="0 0 0" />
      <geometry>
        <box size="0.2 0.0245 0.034"/>
      </geometry>
    </collision>
  </link>
  <joint name="RL_thigh_joint" type="revolute">
    <origin
      xyz="-0.043 0.07525 0"
      rpy="0 0 0" />
    <parent
      link="RL_hip" />
    <child
      link="RL_thigh" />
    <axis
      xyz="0 1 0" />
    <dynamics damping="0" friction="0"/>
    <limit effort="55" lower="-1.0471975512" upper="4.18879020479" velocity="28.6"/>
  </joint>
  <link name="RL_calf">
    <inertial>
      <origin
        xyz="0.00654594639576345 1.54461741741496E-06 -0.0753966803284335"
        rpy="0 0 0" />
      <mass
        value="0.122422317176859" />
      <inertia
        ixx="9.3749108734946E-05"
        ixy="-2.3534371458569E-09"
        ixz="1.03265058974487E-05"
        iyy="0.000110051571045759"
        iyz="-5.39219909611954E-09"
        izz="2.15007107251529E-05" />
    </inertial>
    <visual>
      <origin
        xyz="0 0 0"
        rpy="0 0 0" />
      <geometry>
        <mesh
          filename="../meshes/rl_knee_l.STL" />
      </geometry>
      <material
        name="">
        <color
          rgba="0.752941176470588 0.752941176470588 0.752941176470588 1" />
      </material>
    </visual>
    <collision>
      <origin
        xyz="0 0 0"
        rpy="0 0 0" />
      <geometry>
        <box size="0.2 0.016 0.016"/>
      </geometry>
    </collision>
  </link>
  <joint name="RL_calf_joint" type="revolute">
    <origin
      xyz="-0.0038618 -0.01 -0.16493"
      rpy="0 0 0" />
    <parent
      link="RL_thigh" />
    <child
      link="RL_calf" />
    <axis
      xyz="0 1 0" />
    <dynamics damping="0" friction="0"/>
    <limit effort="55" lower="-2.69653369433" upper="-0.916297857297" velocity="28.6"/>
  </joint>
  <!-- <link
    name="rl_dummy_l">
    <inertial>
      <origin
        xyz="0.0014979844072685 1.99840144432528E-15 7.77349055681165E-05"
        rpy="0 0 0" />
      <mass
        value="9.42477796076945E-06" />
      <inertia
        ixx="4.72504481421764E-12"
        ixy="-2.75052131823419E-27"
        ixz="-2.43883254369304E-13"
        iyy="9.42477796076952E-12"
        iyz="2.68212707776922E-29"
        izz="9.41212212693661E-12" />
    </inertial>
    <visual>
      <origin
        xyz="0 0 0"
        rpy="0 0 0" />
      <geometry>
        <mesh
          filename="../meshes/rl_dummy_l.STL" />
      </geometry>
      <material
        name="">
        <color
          rgba="0.792156862745098 0.819607843137255 0.933333333333333 1" />
      </material>
    </visual>
    <collision>
      <origin
        xyz="0 0 0"
        rpy="0 0 0" />
      <geometry>
        <mesh
          filename="../meshes/rl_dummy_l.STL" />
      </geometry>
    </collision>
  </link> -->
  <link name="FR_foot">
    <inertial>
        <origin xyz="0.0014979844072685 1.99840144432528E-15 7.77349055681165E-05"
        rpy="0 0 0" /> 
        <mass value="0.025" />
        <inertia ixx="2e-6" ixy="0" ixz="0" iyy="2e-6" iyz="0" izz="2e-6" />
      </inertial>
      <visual>
        <origin xyz="0 0 0" rpy="0 0 0" />
        <geometry>
          <sphere radius="0.01" />
        </geometry>
      </visual>
      <collision>
        <origin xyz="0 0 0" rpy="0 0 0" />
        <geometry>
          <sphere radius="0.01" />
        </geometry>
      </collision>
  </link>
  <link name="FL_foot">
    <inertial>
        <origin xyz="0.0014979844072685 1.99840144432528E-15 7.77349055681165E-05"
        rpy="0 0 0" /> 
        <mass value="0.025" />
        <inertia ixx="2e-6" ixy="0" ixz="0" iyy="2e-6" iyz="0" izz="2e-6" />
      </inertial>
      <visual>
        <origin xyz="0 0 0" rpy="0 0 0" />
        <geometry>
          <sphere radius="0.01" />
        </geometry>
      </visual>
      <collision>
        <origin xyz="0 0 0" rpy="0 0 0" />
        <geometry>
          <sphere radius="0.01" />
        </geometry>
      </collision>
  </link>
  <link name="RL_foot">
    <inertial>
        <origin xyz="0.0014979844072685 1.99840144432528E-15 7.77349055681165E-05"
        rpy="0 0 0" /> 
        <mass value="0.025" />
        <inertia ixx="2e-6" ixy="0" ixz="0" iyy="2e-6" iyz="0" izz="2e-6" />
      </inertial>
      <visual>
        <origin xyz="0 0 0" rpy="0 0 0" />
        <geometry>
          <sphere radius="0.01" />
        </geometry>
      </visual>
      <collision>
        <origin xyz="0 0 0" rpy="0 0 0" />
        <geometry>
          <sphere radius="0.01" />
        </geometry>
      </collision>
  </link>
  <link name="RR_foot">
    <inertial>
        <origin xyz="0.0014979844072685 1.99840144432528E-15 7.77349055681165E-05"
        rpy="0 0 0" /> 
        <mass value="0.025" />
        <inertia ixx="2e-6" ixy="0" ixz="0" iyy="2e-6" iyz="0" izz="2e-6" />
      </inertial>
      <visual>
        <origin xyz="0 0 0" rpy="0 0 0" />
        <geometry>
          <sphere radius="0.01" />
        </geometry>
      </visual>
      <collision>
        <origin xyz="0 0 0" rpy="0 0 0" />
        <geometry>
          <sphere radius="0.01" />
        </geometry>
      </collision>
  </link>
  <joint name="RL_foot_fixed" type="fixed" dont_collapse="true" >
    <origin
      xyz="-0.0185 0 -0.16802"
      rpy="0 0 0" />
    <parent
      link="RL_calf" />
    <child
      link="RL_foot" />
  </joint>
</robot>